Workbook

Sheet nháp
A1: STT | B1: Tên trường đối tác | C1: Tên môn tại trường đối tác | D1: Mã môn tại trường đối tác | F1: Tên môn tại FTU | G1: Mã môn tại FTU | H1: Tình trạng
A2: 1 | B2: Hitotsubashi University | C2: 社会科学入門（経済学） | D2: 1DB10501 | F2: Tiếng Nhật Kinh tế | G2: TNHH303 | H2: Tương đương
A3: 2 | B3: Hitotsubashi University | C3: マーケティング・マネジメント | D3: 1BB20801 | F3: Tiếng Nhật Marketing quốc tế | G3: TNHH402 | H3: Tương đương
A4: 3 | B4: Hitotsubashi University | C4: 金融入門 | D4: 1BA12401 | F4: Tiếng Nhật Tài chính | G4: TNHH308 | H4: Tương đương
A5: 4 | B5: Hitotsubashi University | C5: 経営組織 | D5: 2BG50501 | F5: Tiếng Nhật Quản trị | G5: TNHH304 | H5: Tương đương
B6: Hitotsubashi University | C6: 経営組織 | D6: 2BF50501 | F6: Tiếng Nhật Quản trị | G6: TNHH304
A7: 5 | B7: Hitotsubashi University | C7: 経営哲学 | D7: 2BF50801 | F7: Tiếng Nhật Quản trị | G7: TNHH304 | H7: Tương đương
A8: 6 | B8: Hitotsubashi University | C8: 経営組織 | D8: 2BG50501 | E8: =H8& "với học phần "&F8 -> Không tương đương với học phần Tiếng Nhật kinh doanh quốc tế | F8: Tiếng Nhật kinh doanh quốc tế | G8: TNHH307 | H8: Không tương đương
B9: Hitotsubashi University | C9: 経営組織 | D9: 2BF50501 | E9: =H9& "với học phần "&F9 -> Không tương đương với học phần Tiếng Nhật kinh doanh quốc tế | F9: Tiếng Nhật kinh doanh quốc tế | G9: TNHH307 | H9: Không tương đương
A10: 7 | B10: Hitotsubashi University | C10: 経営者講義A | D10: 1BA12101 | E10: =H10& "với học phần "&F10 -> Không tương đương với học phần Tiếng Nhật kinh doanh quốc tế | F10: Tiếng Nhật kinh doanh quốc tế | G10: TNHH307 | H10: Không tương đương
A11: 8 | B11: Hitotsubashi University | C11: 特別講義（企業経営分析） | D11: 1BF45101 | E11: =H11& "với học phần "&F11 -> Không tương đương với học phần Tiếng Nhật kinh doanh quốc tế | F11: Tiếng Nhật kinh doanh quốc tế | G11: TNHH307 | H11: Không tương đương
A12: 9 | B12: Hitotsubashi University | C12: 企業金融の理論と実務（みずほ証券寄附講義） | D12: 1BB35501 | E12: =H12& "với học phần "&F12 -> Không tương đương với học phần Tiếng Nhật Tài chính | F12: Tiếng Nhật Tài chính | G12: TNHH308 | H12: Không tương đương
A13: 10 | B13: Hitotsubashi University | C13: マネジメント・コントロール | D13: 2BG50601 | E13: =H13& "với học phần "&F13 -> Không tương đương với học phần Tiếng Nhật Quản trị học | F13: Tiếng Nhật Quản trị học | G13: TNHH304 | H13: Không tương đương
A14: 11 | B14: Hitotsubashi University | C14: 経済学入門 | D14: 1EA10103 | E14: =H14& "với học phần "&F14 -> Không tương đương với học phần Tiếng Nhật Kinh tế | F14: Tiếng Nhật Kinh tế | G14: TNHH303 | H14: Không tương đương
A15: 12 | B15: Waseda University | C15: グローバルビジネス論 ２ | D15: MANX241L | F15: Tiếng Nhật kinh doanh quốc tế | G15: TNHH307 | H15: Tương đương
A16: 13 | B16: Waseda University | C16: 経営戦略 | D16: MANX231L | F16: Tiếng Nhật quản trị học | G16: TNHH304 | H16: Tương đương
A17: 14 | B17: Waseda University | C17: 経営学 | D17: MANX101L | F17: Tiếng Nhật quản trị học | G17: TNHH304 | H17: Tương đương
A18: 15 | B18: Waseda University | C18: マーケティング論 | D18: CMMM101L | F18: Tiếng Nhật Marketing quốc tế | G18: TNHH402 | H18: Tương đương
A19: 16 | B19: Waseda University | C19: マーケティング戦略論 | D19: CMMM401L | F19: Tiếng Nhật Marketing quốc tế | G19: TNHH402 | H19: Tương đương
A20: 17 | B20: Waseda University | C20: 国際商務論 | D20: CMMI331L | F20: Tiếng Nhật giao dịch thương mại quốc tế | G20: TNHH403 | H20: Tương đương
A21: 18 | B21: Waseda University | C21: 貿易契約論 | D21: CMMI431L | E21: =H21& "với học phần "&F21 -> Không tương đươngvới học phần Tiếng Nhật giao dịch thương mại quốc tế | F21: Tiếng Nhật giao dịch thương mại quốc tế | G21: TNHH403 | H21: Không tương đương
A22: 19 | B22: Waseda University | C22: 国際貿易理論 | D22: CMMI451L | E22: =H22& "với học phần "&F22 -> Không tương đươngvới học phần Tiếng Nhật giao dịch thương mại quốc tế | F22: Tiếng Nhật giao dịch thương mại quốc tế | G22: TNHH403 | H22: Không tương đương
A23: 20 | B23: Waseda University | C23: ミクロ経済学 | D23: ECNE201L | F23: Tiếng Nhật kinh tế | G23: TNHH303 | H23: Tương đương
A24: 21 | B24: Waseda University | C24: マクロ経済学 | D24: ECNE201L | F24: Tiếng Nhật kinh tế | G24: TNHH303 | H24: Tương đương
A25: 22 | B25: Waseda University | C25: 基礎経済学 | D25: ECNE101L | F25: Tiếng Nhật kinh tế | G25: TNHH303 | H25: Tương đương
A26: 23 | B26: Waseda University | C26: 金融入門 | D26: ECNA121L | F26: Tiếng Nhật Tài chính quốc tế | G26: TNHH308 | H26: Tương đương
A27: 24 | B27: Waseda University | C27: 金融論 | D27: ECNA221L | E27: =H27& "với học phần "&F27 -> Không tương đươngvới học phần Tiếng Nhật Tài chính quốc tế | F27: Tiếng Nhật Tài chính quốc tế | G27: TNHH308 | H27: Không tương đương

Sheet Tổng
A1: _ | B1: Nước | C1: Trường đối tác | D1: Tên môn tại trường đối tác | E1: Mã môn tại trường đối tác | F1: Tên môn tại FTU | G1: Mã môn tại FTU | H1: Chương trình | I1: Khoa/Viện | J1: Trưởng bộ môn xác nhận | K1: Thời gian ký nhận
A2: Asia | B2: China | C2: Shanghai University of Finance and Economics | D2: Anglo-American Contract Law | E2: 101808 | F2: Đang xét tương đương với học phần Pháp Luật Thương mại quốc tế | G2: PLU422, PLUE422, PLU422E | H2: Tiêu chuẩn, CLC, CTTT | I2: Luật
A3: Asia | B3: China | C3: Shanghai University of Finance and Economics | D3: Big Data Methods and Applications | E3: 0304 | F3: Lập trình cho phân tích dữ liệu và tính toán Khoa học (Programming for Data Analysis and Scientific Computing) | G3: TIN314, TINE314, TIN314E | H3: Tiêu chuẩn, CLC, CTTT | I3: Khoa CN&KHDL | J3: Nguyễn Văn Tăng | K3: 2026
A4: Asia | B4: China | C4: Shanghai University of Finance and Economics | D4: Corporate Finance | E4: 105512 | F4: Tài chính doanh nghiệp (Corporate Finance) | G4: TCHE321 | H4: CLC | I4: TCNH | J4: Nguyễn Việt Dũng | K4: 2026
A5: Asia | B5: China | C5: Shanghai University of Finance and Economics | D5: Corporate Finance | E5: 105512 | F5: Tài chính doanh nghiệp (Corporate Finance) | G5: TCH321E | H5: CTTT | I5: TCNH | J5: Nguyễn Việt Dũng
A6: Asia | B6: China | C6: Shanghai University of Finance and Economics | D6: Development Economics | E6: 5106 | F6: Không tương đương với học phần Kinh tế phát triển (Development Economics) | G6: KTEE406 | H6: CTTT | I6: KTQT | J6: Lý Hoàng Phú | K6: 2026
A7: Asia | B7: China | C7: Shanghai University of Finance and Economics | D7: Econometrics | E7: 108402 | F7: Kinh tế lượng (Econometrics) | G7: KTE309, KTEE309, KTE309E | H7: Tiêu chuẩn, CLC, CTTT | I7: KTQT | J7: Đinh Thị Thanh Bình | K7: 2026
A8: Asia | B8: China | C8: Shanghai University of Finance and Economics | D8: Financial Accounting | E8: 101314 | F8: Nguyên lý kế toán (Principles of Accounting) | G8: KET201, KETE201, KET201E | H8: Tiêu chuẩn, CLC, CTTT | I8: KTKT | J8: Trần Thị Kim Anh | K8: 2026
A9: Asia | B9: China | C9: Shanghai University of Finance and Economics | D9: Financial Accounting | E9: 101314 | F9: Kế toán tài chính (Financial Accounting) | G9: KETE301 | H9: Tiêu chuẩn, CLC, CTTT | I9: KTKT | J9: Trần Thị Kim Anh | K9: 2026
A10: Asia | B10: China | C10: Shanghai University of Finance and Economics | D10: Financial Instruments and Risk Management | E10: 103097 | F10: Quản trị rủi ro tài chính (Financial Risk Management) | G10: TCH409. TCHE409, TCH409E | H10: Tiêu chuẩn, CLC, CTTT | I10: TCNH | J10: Nguyễn Việt Dũng | K10: 2026
A11: Asia | B11: China | C11: Shanghai University of Finance and Economics | D11: Game Theory and Information Economics | E11: 101561 | F11: Không tương đương với học phần Tổ chức ngành (Industrial Organization) | G11: KTE408, KTEE408, KTE408E | H11: Tiêu chuẩn, CLC, CTTT | I11: KTQT | J11: Từ Thúy Anh | K11: 2026
A12: Asia | B12: China | C12: Shanghai University of Finance and Economics | D12: Game Theory and Information Economics | E12: 1414 | F12: Không tương đương với học phần Tổ chức ngành (Industrial Organization) | G12: KTE408, KTEE408, KTE408E | H12: Tiêu chuẩn, CLC, CTTT | I12: KTQT | J12: Từ Thúy Anh | K12: 2026
A13: Asia | B13: China | C13: Shanghai University of Finance and Economics | D13: Intermediate Macroeconomics | E13: 101562 | F13: Kinh tế vĩ mô 2 (Intermediate Macroeconomics) | G13: KTE402, KTEE402, KTE402E | H13: Tiêu chuẩn, CLC, CTTT | I13: KTQT | J13: Đinh Thị Thanh Bình | K13: 2026
A14: Asia | B14: China | C14: Shanghai University of Finance and Economics | D14: Intermediate Macroeconomics | E14: 1353 | F14: Kinh tế vĩ mô 2 (Intermediate Macroeconomics) | G14: KTEE402 | H14: CLC | I14: KTQT | J14: Đinh Thị Thanh Bình | K14: 2026
A15: Asia | B15: China | C15: Shanghai University of Finance and Economics | D15: International Finance: Theory and Practice | E15: 250246 | F15: Không tương đương với học phần Thanh toán quốc tế (International Payment) | G15: TCH412, TCHE412, TCH412E | H15: Tiêu chuẩn, CLC, CTTT | I15: TCNH | J15: Mai Thu Hiền | K15: 2024 | L15: =COUNTIF(J:J,"") -> 1229
A16: Asia | B16: China | C16: Shanghai University of Finance and Economics | D16: International Trade Law | E16: 311199 | F16: Không tương đương với học phần Giao dịch thương mại quốc tế (International Trade Transactions) | G16: TMA302, TMAE302, TMAH302, TMA302E | H16: Tiêu chuẩn, CLC, CTTT | I16: Viện KT&KDQT | J16: Phan Thị Thu Hiền | K16: 2024
A17: Asia | B17: China | C17: Shanghai University of Finance and Economics | D17: International Trade Law | E17: 311199 | F17: Không tương đương với học phần Chính sách thương mại quốc tế (International Trade Policy) | G17: TMA301, TMAH301, TMA301E | H17: Tiêu chuẩn, CLC, CTTT | I17: Viện KT&KDQT | J17: Vũ Thành Toàn | K17: 2024
A18: Asia | B18: China | C18: Shanghai University of Finance and Economics | D18: Optimization in Finance | E18: 106276 | F18: Đang xét tương đương với học phần Kinh tế học tài chính (Financial Economics) | G18: TCH341, TCHE341, TCH341E | H18: Tiêu chuẩn, CLC, CTTT | I18: TCNH
A19: Asia | B19: China | C19: Shanghai University of Finance and Economics | D19: Public Finance | E19: 102041 | F19: Tài chính công (Public Finance) | G19: TCH431 | H19: Tiêu chuẩn | I19: TCNH | J19: Nguyễn Thu Thủy | K19: 2026
A20: Asia | B20: China | C20: Shanghai University of Finance and Economics | D20: Public Policy | E20: 2147 | F20: Chính sách công (Public Policy) | G20: KTEE441 | H20: CLC | I20: KTQT | J20: Lý Hoàng Phú | K20: 2026
A21: Asia | B21: China | C21: Shanghai University of Finance and Economics | D21: Public Policy | E21: 100729 | F21: Chính sách công (Public Policy) | G21: KTE441, KTEE441, KTE441E | H21: Tiêu chuẩn, CLC, CTTT | I21: KTQT | J21: Lý Hoàng Phú | K21: 2026
A22: Asia | B22: China | C22: SouthWest University | D22: 《面向对象程序设计：C++》 | E22: 33320890 | F22: Lập trình hướng đối tượng (Object-Oriented Programming) | G22: COSH203 | H22: ĐHNNQT | I22: CN&KHDL
A23: Asia | B23: China | C23: SouthWest University | D23: 《计算与智能技术导论》 | E23: 21116644 | F23: Nhập môn AI và Khoa học dữ liệu (Introduction to AI and Data Science) | G23: COSH202 | H23: ĐHNNQT | I23: CN&KHDL
A24: Asia | B24: China | C24: SouthWest University | D24: 《计算机网路网络技术》 | E24: 33310870 | F24: Mạng máy tính (Computer Networks) | G24: COSH201 | H24: ĐHNNQT | I24: CN&KHDL
A25: Asia | B25: China | C25: Beijing Foreign Studies University | D25: Application of Information Tech | F25: Không tương đương với học phần Lập trình cho phân tích dữ liệu và tính toán khoa học (Programming for Data Analysis and Scientific Computing) | G25: TIN314E, TINH314 | H25: Tiêu chuẩn, CLC | I25: KHDL | J25: Nguyễn Văn Tăng | K25: 2025
A26: Asia | B26: China | C26: Beijing Foreign Studies University | D26: Introduction to Corporate finance | E26: LXS011 | F26: Tài chính doanh nghiệp (Corporate Finance) | G26: TCH321, TCHE321, TCH321E | H26: Tiêu chuẩn, CLC, CTTT | I26: TCNH | J26: Nguyễn Việt Dũng | K26: 2025
A27: Asia | B27: China | C27: Beijing Foreign Studies University | D27: Big Data Analysis | E27: BSZXS11 | F27: Đang xét tương đương với học phần Lập trình cho phân tích dữ liệu và tính toán Khoa học (Programming for Data Analysis and Scientific Computing) | G27: TIN314E, TINH314, TINE314, TIN314E | H27: Tiêu chuẩn, CLC, CTTT | I27: CN&KHDL
A28: Asia | B28: China | C28: Beijing Foreign Studies University | D28: Business communication | E28: LXS029 | F28: Không tương đương với học phần Truyền thông trong kinh doanh quốc tế (International Business Communication) | G28: MKT408, MKTE408, MKT408E | H28: Tiêu chuẩn, CLC, CTTT | I28: Viện KT&KDQT | J28: Nguyễn Thanh Bình | K28: 2025
A29: Asia | B29: China | C29: Beijing Foreign Studies University | D29: Business communication | F29: Không tương đương với học phần Văn hóa trong kinh doanh (Culture in Business) | G29: KTE325, KTEE325, KTE325E | H29: Tiêu chuẩn, CLC, CTTT | I29: Viện KT&KDQT | J29: Trần Thị Thu Hiền | K29: 2025
A30: Asia | B30: China | C30: Beijing Foreign Studies University | D30: Business Ethics | F30: Đạo đức kinh doanh (Business Ethics) | G30: QTR305, QTRE305, QTR305E | H30: Tiêu chuẩn, CLC, CTTT | I30: QTKD | J30: Ngô Quý Nhâm | K30: 2025
A31: Asia | B31: China | C31: Beijing Foreign Studies University | D31: Business Law | F31: Pháp luật kinh doanh quốc tế (International Business Law) | G31: PLU410, PLUE410, PLU410E | H31: Tiêu chuẩn, CLC, CTTT | I31: Luật | J31: Nguyễn Minh Hằng | K31: 2025
A32: Asia | B32: China | C32: Beijing Foreign Studies University | D32: Brand Management | F32: Thương hiệu trong kinh doanh quốc tế (Brand in International Business) | G32: MKT407, MTKE407, MKT407E | H32: Tiêu chuẩn, CLC, CTTT | I32: Viện KT&KDQT | J32: Vũ Thành Toàn | K32: 2025
A33: Asia | B33: China | C33: Beijing Foreign Studies University | D33: Cross Cultural Management | F33: Văn hóa trong kinh doanh (Culture in Business) | G33: KTE325, KTEE325, KTE325E | H33: Tiêu chuẩn, CLC, CTTT | I33: Viện KT&KDQT | J33: Phan Thị Thu Hiền | K33: 2025
A34: Asia | B34: China | C34: Beijing Foreign Studies University | D34: Cross Cultural Management | F34: Quản trị đa văn hóa | G34: QTR408, QTRE408, QTR408E | H34: Tiêu chuẩn, CLC, CTTT | I34: QTKD | J34: Ngô Quý Nhâm | K34: 2026
A35: Asia | B35: China | C35: Beijing Foreign Studies University | D35: Data Analytics | F35: Không tương đương với học phần Phân tích dữ liệu trong kinh doanh (Business Analytics) | G35: VJP205, VJPE205, VJP205E | H35: Tiêu chuẩn, CLC., CTTT | I35: VJCC | J35: Hoàng Anh Duy | K35: 2025
A36: Asia | B36: China | C36: Beijing Foreign Studies University | D36: E-Commerce in China | F36: Thương mại điện tử | G36: TMA306, TMAE306, TMA306E | H36: Tiêu chuẩn, CLC, CTTT | I36: Viện KT&KDQT | J36: Nguyễn Hồng Quân | K36: 2026
A37: Asia | B37: China | C37: Beijing Foreign Studies University | D37: Human Resource Management | F37: Quản trị nguồn nhân lực | G37: QTR403, QTRE403, QTR403E | H37: Tiêu chuẩn, CLC, CTTT | I37: QTKD | J37: Ngô Quý Nhâm | K37: 2026
A38: Asia | B38: China | C38: Beijing Foreign Studies University | D38: International Finance | F38: Không tương đương với học phần Tài chính quốc tế (International Finance) | G38: TCH414, TCHE414, TCH414E | H38: Tiêu chuẩn, CLC, CTTT | I38: TCNH | J38: Mai Thu Hiền | K38: 2025
A39: Asia | B39: China | C39: Beijing Foreign Studies University | D39: International Trade | F39: Chính sách thương mại quốc tế (International Trade Policy) | G39: TMA301, TMAE301, TMA301E | H39: Tiêu chuẩn, CLC, CTTT | I39: Viện KT&KDQT | J39: Vũ Thành Toàn | K39: 2025
A40: Asia | B40: China | C40: Beijing Foreign Studies University | D40: Introduction to Business | F40: Nhập môn kinh doanh (Introduction to Business) | G40: KDO203, KDOE203, KDO203E | H40: Tiêu chuẩn, CLC, CTTT | I40: Viện KT&KDQT | J40: Trần Thị Thu Hiền | K40: 2025
...

Sheet Count trưởng bộ môn
A1: STT | B1: Trưởng bộ môn xác nhận | C1: Đếm môn
A2: 1 | B2: Nguyễn Thị Bích Huệ | C2: =countif('Tổng'!J:J,B2) -> 317
A3: 2 | B3: Nguyễn Việt Dũng | C3: =countif('Tổng'!J:J,B3) -> 260
A4: 3 | B4: Ngô Quý Nhâm | C4: =countif('Tổng'!J:J,B4) -> 312
A5: 4 | B5: Nguyễn Thanh Bình | C5: =countif('Tổng'!J:J,B5) -> 287
A6: 5 | B6: Phan Thị Thu Hiền | C6: =countif('Tổng'!J:J,B6) -> 241
A7: 6 | B7: Phạm Quang Hưng | C7: =countif('Tổng'!J:J,B7) -> 152
A8: 7 | B8: Vũ Thành Toàn | C8: =countif('Tổng'!J:J,B8) -> 272
A9: 8 | B9: Lê Thái Phong | C9: =countif('Tổng'!J:J,B9) -> 219
A10: 9 | B10: Mai Thu Hiền | C10: =countif('Tổng'!J:J,B10) -> 117
A11: 10 | B11: Từ Thuý Anh | C11: =countif('Tổng'!J:J,B11) -> 88
A12: 11 | B12: Trịnh Thị Thu Hương | C12: =countif('Tổng'!J:J,B12) -> 152
A13: 12 | B13: Trần Thị Kim Anh | C13: =countif('Tổng'!J:J,B13) -> 104
... A49: 48 | B49: Nguyễn Thị Thuỳ Vinh | C49: =countif('Tổng'!J:J,B49) -> 1

Sheet Stage 3 Outbound recheck
A2: Chưa có chữ ký của trưởng bộ môn | B2: Asia | C2: Japan | D2: Fukuyama University | E2: Giới thiệu về kinh tế học | G2: Không tương đương với học phần nào của bộ môn
A3: Chưa có chữ ký của trưởng bộ môn | B3: Asia | C3: Japan | D3: Fukuyama University | E3: Kinh tế Mỹ II | G3: Không tương đương với học phần nào của bộ môn
A4: Chưa có chữ ký của trưởng bộ môn | B4: Asia | C4: Japan | D4: Fukuyama University | E4: Seminar in English II | G4: Không tương đương với học phần nào của bộ môn
A5: Chưa có chữ ký của trưởng bộ môn | B5: Asia | C5: Japan | D5: Fukuyama University | E5: Tiếng Anh IV | G5: Không tương đương với học phần nào của bộ môn
A6: 25 | B6: Asia | C6: Japan | D6: Hiroshima University of Economics | E6: 交換留学日本語（上級AI | F6: 36027 | G6: Ngoại ngữ 4 | H6: TNH232 | I6: Tiêu chuẩn | J6: KTĐN
A7: 26 | B7: Asia | C7: Japan | D7: Hiroshima University of Economics | E7: 交換留学日本語（上級AI | F7: 36027 | G7: Ngoại ngữ 5 | H7: TNH331 | I7: Tiêu chuẩn | J7: KTĐN
A8: 27 | B8: Asia | C8: Japan | D8: Hiroshima University of Economics | E8: 交換留学日本語（上級BI | F8: 36029 | G8: Ngoại ngữ 4 | H8: TNH232 | I8: Tiêu chuẩn | J8: KTĐN
A9: 28 | B9: Asia | C9: Japan | D9: Hiroshima University of Economics | E9: 交換留学日本語（上級BI | F9: 36029 | G9: Ngoại ngữ 5 | H9: TNH331 | I9: Tiêu chuẩn | J9: KTĐN
A10: 44 | B10: Asia | C10: Japan | D10: Hitotsubashi University | E10: 日本語中上級(漢字語彙) | G10: Từ vựng tiếng Nhật nâng cao | H10: TNH226 | I10: Tiêu chuẩn | J10: Tiếng Nhật
B11: Asia | C11: Japan | D11: Hitotsubashi University | E11: Corporate Finance | G11: Không tương đương với học phần Tài chính Quốc tế
A12: 17 | B12: Asia | C12: Japan | D12: Hitotsubashi University | E12: ビジネス・コミュニケーション… | G12: Không tương đương với Nghe - đọc thương mại 1
A13: 18 | B13: Asia | C13: Japan | D13: Hitotsubashi University | E13: ビジネス・コミュニケーション… | G13: Không tương đương với Nghe - đọc thương mại 2
B14: Asia | C14: Japan | D14: Hitotsubashi University | E14: Special Topics on Management and Marketing E | F14: 1BB38501 | G14: Kỹ năng lãnh đạo và phát triển cá nhân | H14: QTRE203; QTR203; QTR203E
B15: Asia | C15: Japan | D15: Hitotsubashi University | E15: Interactive Course on Business Basics (Finance) | F15: 1BB27601 | G15: Khoa đề xuất tương đương với học phần Quản trị tài chính doanh nghiệp (KET307) tuy nhiên cần bổ sung giải thích credit của trường Hitotsubashi
A16: Chưa có chữ ký của trưởng bộ môn | B16: Asia | C16: Japan | D16: Hitotsubashi University | E16: 特別講義 (社会課題の解決) | F16: 1BB36101 | G16: Không tương đương với học phần Đạo đức kinh doanh và trách nhiệm xã hội | H16: KDOH305 | I16: CLC
A19: 58 | B19: Asia | C19: Japan | D19: J. F. Oberlin University | E19: 国際貿易論 | F19: 22384 | G19: Tiếng Nhật giao dịch thương mại quốc tế | H19: TNHH403 | I19: CLC | J19: Tiếng Nhật
A20: 57 | B20: Asia | C20: Japan | D20: J. F. Oberlin University | E20: 国際貿易論 | F20: 22384 | G20: Ngôn ngữ KTTM 3: Giao dịch thương mại | H20: TNH404 | I20: Tiêu chuẩn | J20: Tiếng Nhật
A21: 55 | B21: Asia | C21: Japan | D21: J. F. Oberlin University | E21: 日本の文化（Ｅ）（GS_RL） | F21: 285034 | G21: Văn hóa văn minh Nhật Bản | H21: TNH315 | I21: Tiêu chuẩn | J21: Tiếng Nhật
A22: 56 | B22: Asia | C22: Japan | D22: J. F. Oberlin University | E22: 日本の文化（Ｅ）（GS_RL） | F22: 285034 | G22: Xã hội Nhật Bản | H22: TNHH210 | I22: CLC | J22: Tiếng Nhật
A23: 59 | B23: Asia | C23: Japan | D23: J. F. Oberlin University | E23: 異文化経営論 | F23: 26184 | G23: Tiếng Nhật Kinh doanh QT | H23: TNHH307 | I23: CLC | J23: Tiếng Nhật
B24: Asia | C24: Japan | D24: J. F. Oberlin University | E24: キャリアデザインD (留学生用) | F24: 201461 | G24: Định hướng nghề nghiệp | H24: TNHH502
B25: Asia | C25: Japan | D25: J. F. Oberlin University | E25: キャリアデザインD (LA・GC・健福-a) | F25: 201455 | G25: Định hướng nghề nghiệp | H25: TNHH502
B26: Asia | C26: Japan | D26: J. F. Oberlin University | E26: 国際マーケティング研究 | F26: 32112 | G26: Tiếng Nhật marketing quốc tế | H26: TNHH402
A27: 95 | B27: Asia | C27: Japan | D27: Kansai University | E27: International Business Communication | G27: Viết 3 | H27: TAN304 | I27: TC | J27: TATM
A28: chưa xác nhận tương đương | B28: Asia | C28: Japan | D28: Kansai University | E28: Japanese Economy (Topics in Japanese Economy and Discussion) | F28: 00705 | G28: Tiếng Nhật kinh tế | H28: TNHH303 | I28: CLC | J28: Tiếng Nhật
A29: chưa có link đính kèm | B29: Asia | C29: Japan | D29: Kansai University | E29: Japanese Industries and Companies (The Global Competition) | F29: 00687 | G29: Không tương đương với môn Tiếng Nhật kinh tế | H29: TNHH303 | I29: CLC | J29: Tiếng Nhật
A30: 84 | B30: Asia | C30: Japan | D30: Kansai University | E30: 経営学 | F30: 70352 | G30: Không tương đương môn thuộc khoa QTKD
B31: Asia | C31: Japan | D31: Kansai University | E31: International Business for Entrepreneurs | F31: 00680 | G31: Không tương đương với học phần English for Specific Purpose 5 (Public speaking)
B32: Asia | C32: Japan | D32: Kansai University | E32: Communication in Japanese Society (Business Japanese) | F32: 05132 | G32: Tiếng Nhật thương mại trung cấp 3,4 | H32: TNHH206, TNHH207
B33: Asia | C33: Japan | D33: Kansai University | E33: Communication in Japanese Society (Business Japanese) | F33: 05132 | G33: Tiếng Nhật thương mại trung cao cấp 1,2 | H33: TNHH301, TNHH302
B34: Asia | C34: Japan | D34: Kansai University | E34: International Political Economy 2 | F34: 30719 | G34: Không tương đương với học phần Pháp luật thương mại và kinh doanh quốc tế
B35: Asia | C35: Japan | D35: Kansai University | E35: International Business for Entrepreneurs | F35: 00680 | G35: Không tương đương Xây dựng dự án kinh doanh
B36: Asia | C36: Japan | D36: Kansai University | E36: 国際経済学２ | F36: 30628 | G36: Không tương đương với học phần Tiếng Nhật Kinh doanh Quốc tế
B37: Asia | C37: Japan | D37: Kansai University | E37: 経済学特殊講義１(実験で学ぶ経済学ー実験経済入門ー) | F37: 30730 | G37: Tiếng Nhật kinh tế | H37: TNHH303
B38: Asia | C38: Japan | D38: Kansai University | E38: 国際金融論 1 | F38: 30706 | G38: Không tương đương với học phần Tài chính quốc tế | J38: Khoa Tài chính ngân hàng
B39: Asia | C39: Japan | D39: Kansai University | E39: Communication in Japanese Society (Business Japanese) | F39: 05312 | G39: Không tương đương với học phần Tiếng nhật thương mại trung cấp 3
B40: Asia | C40: Japan | D40: Kansai University | E40: Communication in Japanese Society (Business Japanese) | F40: 05312 | G40: Không tương đương với học phần Tiếng nhật thương mại trung cấp 4
B41: Asia | C41: Japan | D41: Kansai University | E41: Communication in Japanese Society (Business Japanese) | F41: 05312 | G41: Không tương đương với học phần Tiếng nhật thương mại trung cao cấp 1
B42: Asia | C42: Japan | D42: Kansai University | E42: Communication in Japanese Society (Business Japanese) | F42: 05312 | G42: Không tương đương với học phần Tiếng nhật thương mại trung cao cấp 2
A43: 2 | B43: Asia | C43: Japan | D43: Kansai University | E43: 国際金融論 1 | F43: 30706 | G43: Không tương đương với học phần Tài chính quốc tế
...

Sheet Rà soát lại
B1: Châu | C1: Nước | D1: Trường đối tác | E1: Tên môn tại trường đối tác | F1: Mã môn tại trường đối tác | G1: Tên môn tại FTU | H1: Mã môn tại FTU | I1: Chương trình | J1: Khoa/Chuyên ngành
B2: Asia | C2: Japan | D2: Doshisha Women's College of Liberal Arts (DWCLA) | E2: Japanese Composition II A | F2: 245760 | G2: Đang xét duyệt với Viết II (Gửi lại 21.08)
B3: Asia | C3: Japan | D3: Doshisha Women's College of Liberal Arts (DWCLA) | E3: Japanese Reading Comprehension II A | F3: 245360 | G3: Đang xét duyệt với Đọc II (Gửi lại 21.08) | H3: TNH306 | I3: Tiêu chuẩn | J3: Tiếng Nhật
B4: Asia | C4: Japan | D4: Hiroshima University of Economics | E4: 交換留学日本語（上級AI | F4: 36027 | G4: Ngoại ngữ 4 | H4: TNH232 | I4: Tiêu chuẩn | J4: KTĐN
B5: Asia | C5: Japan | D5: Hiroshima University of Economics | E5: 交換留学日本語（上級AI | F5: 36027 | G5: Ngoại ngữ 5 | H5: TNH331 | I5: Tiêu chuẩn | J5: KTĐN
B6: Asia | C6: Japan | D6: Hiroshima University of Economics | E6: 交換留学日本語（上級BI | F6: 36029 | G6: Ngoại ngữ 4 | H6: TNH232 | I6: Tiêu chuẩn | J6: KTĐN
B7: Asia | C7: Japan | D7: Hiroshima University of Economics | E7: 交換留学日本語（上級BI | F7: 36029 | G7: Ngoại ngữ 5 | H7: TNH331 | I7: Tiêu chuẩn | J7: KTĐN
B8: Asia | C8: Japan | D8: Hiroshima University of Economics | E8: International management | G8: Không tương đương với Business and economic project practices
B9: Asia | C9: Japan | D9: Hiroshima University of Economics | E9: Practical Management Theory | G9: Không tương đương với Business and economic project practices
B10: Asia | C10: Japan | D10: Hitotsubashi University | E10: 日本語中上級(漢字語彙) | G10: Từ vựng tiếng Nhật nâng cao | H10: TNH226 | I10: Tiêu chuẩn | J10: Tiếng Nhật
B11: Asia | C11: Japan | D11: Hitotsubashi University | E11: Corporate Finance | G11: Không tương đương với học phần Tài chính Quốc tế
B12: Asia | C12: Japan | D12: Hitotsubashi University | E12: Advanced Corporate Finance | F12: 1BE43601 | G12: Không tương đương với học phần Tài chính Quốc tế
B13: Asia | C13: Japan | D13: Hitotsubashi University | E13: 経済の日上級II(留学生用） | G13: Đọc thương mại | H13: TNHH205 | I13: CLC | J13: Tiếng Nhật
B14: Asia | C14: Japan | D14: Hitotsubashi University | E14: 日本語上級 (読解) I | F14: 1GE24202 | G14: Không tương đương với Đọc thương mại
B15: Asia | C15: Japan | D15: Hitotsubashi University | E15: ビジネス・コミュニケーション… | G15: Không tương đương với Nghe - đọc thương mại 1
B16: Asia | C16: Japan | D16: Hitotsubashi University | E16: ビジネス・コミュニケーション… | G16: Không tương đương với Nghe - đọc thương mại 2
B17: Asia | C17: Japan | D17: Hitotsubashi University | E17: 経官戦略論 | G17: Đang chờ xét duyệt môn Kinh doanh quốc tế | H17: KDOH307 | I17: CLC | J17: Tiếng Nhật
B18: Asia | C18: Japan | D18: Hitotsubashi University | E18: Special Topics on Management and Marketing | F18: 1BB38501 | G18: Kỹ năng lãnh đạo và phát triển cá nhân | H18: QTRE203; QTR203; QTR203E
B19: Asia | C19: Japan | D19: Hitotsubashi University | E19: Intermediate Course in Management | F19: 1BB27801 | G19: Hành vi tổ chức | H19: QTRE402; QTR402; QTR402E
B20: Asia | C20: Japan | D20: Hitotsubashi University | E20: Special Topics on Management and Marketing | F20: 1BB38501 | G20: Đạo đức kinh doanh | H20: QTR305E; QTR305; QTRE305
B21: Asia | C21: Japan | D21: Hitotsubashi University | E21: Interactive Course on Business Basics (Finance) | F21: 1BB27601 | G21: Khoa đề xuất tương đương với học phần Quản trị tài chính doanh nghiệp (KET307) tuy nhiên cần bổ sung giải thích credit của trường Hitotsubashi
B22: Asia | C22: Japan | D22: J. F. Oberlin University | E22: 異文化経営論 | F22: 262077 | G22: Quản trị đa văn hóa | H22: QTRH408
B24: Asia | C24: Japan | D24: Kansai University | E24: International Business Communication | G24: Không tương đương với môn Ngôn ngữ kinh tế thương mại 3: Giao tiếp kinh doanh | H24: TAN407 | I24: TC | J24: TATM
B25: Asia | C25: Japan | D25: Kansai University | E25: International Business Communication | G25: Viết 3 | H25: TAN304 | I25: TC | J25: TATM
B26: Asia | C26: Japan | D26: Kansai University | E26: Japanese Industries and Companies (The Global Competition) | F26: 00687 | G26: Không tương đương với môn Tiếng Nhật kinh tế | H26: TNHH303 | I26: CLC | J26: Tiếng Nhật
B27: Asia | C27: Japan | D27: Kansai University | E27: 経営学 | F27: 70352 | G27: Không tương đương môn thuộc khoa QTKD
B28: Asia | C28: Japan | D28: Kansai University | E28: International Business Communication | G28: Không tương đương môn Ngôn ngữ Kinh tế thương mại 3: Giao tiếp Kinh doanh | H28: TAN407 | I28: CTTC | J28: TATM
B29: Asia | C29: Japan | D29: Kansai University | E29: KUGF Independent Study (Doing a Research) | F29: 00875 | G29: Viết 3 | H29: TAN304 | I29: CTTT | J29: TATM
B30: Asia | C30: Japan | D30: Kansai University | E30: Global Awareness II | F30: 00680 | G30: Không tương đương với học phần Global Governance
B31: Asia | C31: Japan | D31: Kansai University | E31: Global Awareness II | F31: 00882 | G31: không tương đương với môn Business Ethics and Corporate Social responsibility
B32: Asia | C32: Japan | D32: Kansai University | E32: International Political Economy 2 | F32: 30719 | G32: Đang chờ xét duyệt môn Pháp luật thương mại và kinh doanh quốc tế
B33: Asia | C33: Japan | D33: Kansai University
B34: Asia | C34: Japan | D34: Kansai University
B35: Asia | C35: Japan | D35: Kansai University | E35: Critical Thinking Skills | G35: Logics and Methodology of Studying and Research (Logic học và phương pháp nghiên cứu khoa học) | H35: TRIH201
B36: Asia | C36: Japan | D36: Kobe University | E36: Global Marketing | F36: 29402 | G36: Maketing trong kinh doanh quốc tế | H36: MKTH 306
B37: Asia | C37: Japan | D37: Kwansei Gakuin University | E37: 会計学基礎 | F37: 34149000 | G37: Ngôn ngữ kinh tế thương mại 6: Tài chính kế toán | H37: TNH410 | I37: TC
B38: Asia | C38: Japan | D38: Kwansei Gakuin University | E38: 経営学 A | F38: 254820 | G38: Ngôn ngữ kinh tế thương mại 8: Quản trị kinh doanh | H38: TNH412
B39: Asia | C39: Japan | D39: Musashino University | E39: Finance B | F39: GBS242 | G39: Tài chính doanh nghiệp | H39: TCH321, TCHE321
B43: Asia | C43: Japan | D43: Meiji University | E43: 国際経済学Ａ | F43: (CO)ECN391J | G43: Đang xét với học phần Ngôn ngữ kinh tế thương mại 1: Quan hệ kinh tế quốc tế | J43: gửi ngày 19/10/2023
B44: Asia | C44: Japan | D44: Meiji University | E44: 日本語7（語彙・文型表現) | F44: (JE)LAN181J | G44: Đang xét với học phân Ngữ pháp tiếng Nhật nâng cao | J44: gửi ngày 19/10/2023
...

Sheet Stage 1 Nhập chờ hệ thống
A1: Ngày nhập hệ thống | B1: Châu | C1: Nước | D1: Trường đối tác | E1: Tên môn tại trường đối tác | F1: Mã môn tại trường đối tác | G1: Tên môn tại FTU | H1: Mã môn tại FTU | I1: Chương trình | J1: Khoa/Chuyên ngành
A2: 44938 | D2: Waseda Universitty | E2: Business Model Creation with AI Technologics beta (for undergraduate) | F2: MANX157L | G2: Thực hành Kinh doanh Quốc tế 1 | H2: KDOE410
A3: 44938 | D3: Waseda Universitty | E3: Communication Strategy English-based Undergraduate program | F3: LANE102E | G3: Tiếng anh chuyên ngành 5 | H3: ESP451
A4: 44938 | D4: Dankook University | E4: Corporate Finance | F4: 467220 | G4: Ngôn ngữ kinh tế Thương mại 5 - Tài chính | H4: TAN410
A5: 44938 | D5: Waseda Universitty | E5: Corporate Finance 1 | F5: 1600004AB3 | G5: Tài chính quốc tế | H5: TCHE414
A6: 44938 | D6: Waseda Universitty | E6: Corporate Finance 1 | F6: 1600004AB3 | G6: Tài chính công | H6: TCHE431
A7: 44938 | D7: Waseda Universitty | E7: English Plus (Public speaking and speech) 01 | F7: LANE303F | G7: Tiếng anh chuyên ngành 5 | H7: ESP451
A8: 44938 | D8: Waseda Universitty | E8: Entertainment Business Strategy | F8: MANX631L | G8: Kinh tế học cái hoạt dọng giải trí ngoài trời | H8: AREC346
A9: 44938 | D9: Yonsei University | E9: Financial Management | F9: MGT3016.01 - 01 | G9: Phân tích và đầu tư chứng khoán | H9: DTU401E
A10: 44938 | D10: Hasselt University | E10: Human Resource Management | F10: 3709 | G10: Human Resource Management | H10: QTR403E
A11: 44938 | D11: Hasselt University | E11: Human Resource Management | F11: 3709 | G11: Principles of economic management | H11: DTU301E
A12: 44938 | D12: University of Mannheim | E12: International Accounting | F12: ACC351 | G12: Kế toán quốc tế | H12: KETE410
A13: 44938 | D13: Friedrich Alexander University Erlangen-Nuremberg (FAU) | E13: International Economics | G13: Kinh tế quốc tế | H13: KTE308
A14: 44938 | D14: Friedrich Alexander University Erlangen-Nuremberg (FAU) | E14: International Economics | G14: Kinh tế quốc tế | H14: KTEE308
A15: 44938 | D15: Friedrich Alexander University Erlangen-Nuremberg (FAU) | E15: International Economics | G15: Kinh tế quốc tế | H15: KTE308E
A16: 44938 | D16: Friedrich Alexander University Erlangen-Nuremberg (FAU) | E16: International Finance | G16: Thị trường tài chính quốc tế
A17: 44938 | D17: Friedrich Alexander University Erlangen-Nuremberg (FAU) | E17: International Finance | G17: Thị trường tài chính quốc tế | H17: TCH403E
A18: 44938 | D18: Friedrich Alexander University Erlangen-Nuremberg (FAU) | E18: International Finance | G18: Thị trường tài chính quốc tế | H18: TCH403
A19: 44938 | D19: Waseda Universitty | E19: International Finance | F19: ECNA121L | G19: Tài chính quốc tế | H19: TCHHE414
A20: 44938 | D20: Waseda Universitty | E20: International Finance | F20: ECNA121L | G20: Tiền tệ_Ngân hàng | H20: TCHE303
A21: 44938 | D21: Waseda Universitty | E21: International Finance | F21: ECNA121L | G21: Quản trị tài chính_Lý thuyết và Ứng dụng | H21: FIN370
A22: 44938 | D22: Waseda Universitty | E22: International Finance | F22: ECNA121L | G22: Tài chính doanh nghiệp | H22: TCHE321
A23: 44938 | D23: Waseda Universitty | E23: International Finance | F23: ECNA121L | G23: Tài chính công | H23: TCHE431
A24: 44938 | D24: Dankook University | E24: International Management | F24: 319960 | G24: Ngôn ngữ Kinh tế Thương mại 2 - Kinh doanh Quốc tế | H24: TAN403
A25: 44938 | D25: Waseda Universitty | E25: Introduction to Language and Communication | F25: LNGT2015 | G25: Tiếng anh chuyên ngành 5 | H25: ESP451
A26: 44938 | D26: Dankook University | E26: Money and Banking | F26: 467290 | G26: Thanh toán quốc tế | H26: TCH412
A27: 44938 | D27: Waseda Universitty | E27: Money and Banking I(E) 01 | F27: ECNA221L | G27: Tiền tệ_Ngân hàng | H27: TCHE303
A28: 44938 | D28: Waseda Universitty | E28: Money and Banking I(E) 01 | F28: ECNA221L | G28: Tài chính doanh nghiệp | H28: TCHE321
A29: 44938 | D29: Waseda Universitty | E29: Money and Banking I(E) 01 | F29: ECNA221L | G29: Tài chính quốc tế | H29: TCHE414
A30: 44938 | D30: Waseda Universitty | E30: Money and Banking I(E) 01 | F30: ECNA221L | G30: Tài chính công | H30: TCHE431
A31: 44938 | D31: Waseda Universitty | E31: Social Business Cooperation Projects | F31: 18G0000146 | G31: Thực hành Kinh doanh Quốc tế 1 | H31: KDOE410
A32: 44938 | D32: Yokohama National University | E32: アカデミックライティング・プレゼンテーション | F32: J514 | G32: Viết thương mại | H32: TNHH305
A33: 44938 | D33: Yokohama National University | E33: 聴く・読む/ Listening and Reading | F33: J512 | G33: Nghe thương mại
A34: 44938 | D34: Yokohama National University | E34: 聴く・読む/ Listening and Reading | F34: J512 | G34: Đọc thương mại
A35: 44968 | D35: Kansai University | E35: Business for Sustainable Development Goals | G35: Social Innovation (Sáng tạo xã hội) | H35: TMAE202
A36: 44968 | D36: Kansai University | E36: Critical Thinking Skills | G36: Logics and Methodology of Study and Research (Logic học và phương pháp học tập, nghiên cứu của khoa học | H36: TRIH200
A37: 44968 | D37: Hannam University | E37: Financial Investment | F37: 25726 | G37: Financial Management in Hospitality | H37: QKSE402
A38: 44968 | D38: University of Augsburg | E38: International Accounting | F38: WIW - 0268 | G38: Kế toán quản trị | H38: KET310E
A39: 44968 | D39: Hasselt University | E39: International Business | F39: 3884 | G39: International Business Communication | H39: MKT408E
A40: 44968 | D40: Neu-Ulm university of Applied Science | E40: International Business | F40: 1282320 | G40: Quản trị & kinh doanh quốc tế (International business & management) | H40: QTRE401
...
